2024-07-22 12:52:50,932 ERROR: Exception on /users/dashboard [GET] [in /home/g304975/virtualenv/nyxmediaa/3.10/lib/python3.10/site-packages/flask/app.py:828]
Traceback (most recent call last):
  File "/home/g304975/virtualenv/nyxmediaa/3.10/lib/python3.10/site-packages/flask/app.py", line 1463, in wsgi_app
    response = self.full_dispatch_request()
  File "/home/g304975/virtualenv/nyxmediaa/3.10/lib/python3.10/site-packages/flask/app.py", line 872, in full_dispatch_request
    rv = self.handle_user_exception(e)
  File "/home/g304975/virtualenv/nyxmediaa/3.10/lib/python3.10/site-packages/flask/app.py", line 870, in full_dispatch_request
    rv = self.dispatch_request()
  File "/home/g304975/virtualenv/nyxmediaa/3.10/lib/python3.10/site-packages/flask/app.py", line 855, in dispatch_request
    return self.ensure_sync(self.view_functions[rule.endpoint])(**view_args)  # type: ignore[no-any-return]
  File "/home/g304975/virtualenv/nyxmediaa/3.10/lib/python3.10/site-packages/flask_login/utils.py", line 290, in decorated_view
    return current_app.ensure_sync(func)(*args, **kwargs)
  File "/home/g304975/nyxmediaa/user/route.py", line 51, in dashboard
    print(courses)
UnicodeEncodeError: 'ascii' codec can't encode character '\xe9' in position 89: ordinal not in range(128)
